Workbook

Sheet Instrucciones
B2: Casos de prueba de Quanela
B3: 307 casos · versión del 7 de octubre de 2026 · basados en el código, la base de datos y el Centro de ayuda
B5: Para qué sirve | C5: Probar a mano todas las funciones de la app: lo que debe funcionar, los errores esperados, los permisos de cada rol y la seguridad entre negocios.
B6: Cómo usarlo | C6: 1. En «Casos de prueba», filtra por módulo, prioridad o rol. 2. Sigue las precondiciones y los pasos. 3. Compara con el resultado esperado. 4. Llena «Estado», «Resultado obtenido», «Ejecutado por» y «Fecha». 5. Si falla, anota el ticket o la descripción en «Defecto / ticket». La hoja «Resumen» se actualiza sola con los estados.
B7: Estados | C7: Pendiente · Pasó · Falló · Bloqueado (no se pudo ejecutar por otra falla o por falta de datos) · No aplica.
B8: Prioridad | C8: Alta: dinero, inventario, permisos, seguridad o flujo principal. Media: funciones secundarias o mensajes. Baja: detalles visuales o de texto.
B9: Tipos | C9: Funcional (camino feliz) · Negativo · Validación · Permisos · Seguridad · Integración (un módulo afecta a otro) · UI/UX · Accesibilidad · Regresión (un error ya corregido no debe volver) · Rendimiento.
B10: Ambiente | C10: Usa una cuenta de prueba, nunca un negocio real. Para Permisos necesitas un usuario por rol: ADMIN, GERENTE, CAJA, COCINA, INVENTARIO y DOMICILIARIO. Para Seguridad, un segundo negocio de prueba.
B11: Datos de prueba | C11: Solo datos ficticios (por ejemplo «Laura Gómez», laura@negocio.co, +57 300 123 4567). No uses teléfonos, correos ni nombres de clientes reales.
B12: Casos con «anotar como defecto» | C12: En unos casos el resultado esperado avisa que, leyendo el código, parece haber un error. El resultado esperado describe cómo debería funcionar; si la app hace otra cosa, márcalo «Falló».
B13: Posibles defectos | C13: La hoja «Posibles defectos» lista lo que se encontró al revisar el código. No se reprodujo en la app: confírmalo con los casos relacionados.
B14: Referencia | C14: La columna «Referencia» indica el archivo, la ADR o el artículo de ayuda que respalda cada caso.

Sheet Resumen
A1: Resumen por módulo
A3: Módulo | B3: Casos | C3: Alta | D3: Media | E3: Baja | F3: Pendiente | G3: Pasó | H3: Falló | I3: Bloqueado | J3: No aplica | K3: % ejecutado | L3: % aprobado
A4: Landing y documentación | B4: =COUNTIF('Casos de prueba'!$B:$B,$A4) | C4: =COUNTIFS('Casos de prueba'!$B:$B,$A4,'Casos de prueba'!$F:$F,"Alta") | D4: =COUNTIFS('Casos de prueba'!$B:$B,$A4,'Casos de prueba'!$F:$F,"Media") | E4: =COUNTIFS('Casos de prueba'!$B:$B,$A4,'Casos de prueba'!$F:$F,"Baja") | F4: =COUNTIFS('Casos de prueba'!$B:$B,$A4,'Casos de prueba'!$L:$L,"Pendiente") | G4: =COUNTIFS('Casos de prueba'!$B:$B,$A4,'Casos de prueba'!$L:$L,"Pasó") | H4: =COUNTIFS('Casos de prueba'!$B:$B,$A4,'Casos de prueba'!$L:$L,"Falló") | I4: =COUNTIFS('Casos de prueba'!$B:$B,$A4,'Casos de prueba'!$L:$L,"Bloqueado") | J4: =COUNTIFS('Casos de prueba'!$B:$B,$A4,'Casos de prueba'!$L:$L,"No aplica") | K4: =IF(B4-J4=0,0,(G4+H4+I4)/(B4-J4)) | L4: =IF(G4+H4=0,0,G4/(G4+H4))
A5: Acceso y cuenta | B5: =COUNTIF('Casos de prueba'!$B:$B,$A5) | C5: =COUNTIFS('Casos de prueba'!$B:$B,$A5,'Casos de prueba'!$F:$F,"Alta") | D5: =COUNTIFS('Casos de prueba'!$B:$B,$A5,'Casos de prueba'!$F:$F,"Media") | E5: =COUNTIFS('Casos de prueba'!$B:$B,$A5,'Casos de prueba'!$F:$F,"Baja") | F5: =COUNTIFS('Casos de prueba'!$B:$B,$A5,'Casos de prueba'!$L:$L,"Pendiente") | G5: =COUNTIFS('Casos de prueba'!$B:$B,$A5,'Casos de prueba'!$L:$L,"Pasó") | H5: =COUNTIFS('Casos de prueba'!$B:$B,$A5,'Casos de prueba'!$L:$L,"Falló") | I5: =COUNTIFS('Casos de prueba'!$B:$B,$A5,'Casos de prueba'!$L:$L,"Bloqueado") | J5: =COUNTIFS('Casos de prueba'!$B:$B,$A5,'Casos de prueba'!$L:$L,"No aplica") | K5: =IF(B5-J5=0,0,(G5+H5+I5)/(B5-J5)) | L5: =IF(G5+H5=0,0,G5/(G5+H5))
A6: Equipo | B6: =COUNTIF('Casos de prueba'!$B:$B,$A6) | C6: =COUNTIFS('Casos de prueba'!$B:$B,$A6,'Casos de prueba'!$F:$F,"Alta") | D6: =COUNTIFS('Casos de prueba'!$B:$B,$A6,'Casos de prueba'!$F:$F,"Media") | E6: =COUNTIFS('Casos de prueba'!$B:$B,$A6,'Casos de prueba'!$F:$F,"Baja") | F6: =COUNTIFS('Casos de prueba'!$B:$B,$A6,'Casos de prueba'!$L:$L,"Pendiente") | G6: =COUNTIFS('Casos de prueba'!$B:$B,$A6,'Casos de prueba'!$L:$L,"Pasó") | H6: =COUNTIFS('Casos de prueba'!$B:$B,$A6,'Casos de prueba'!$L:$L,"Falló") | I6: =COUNTIFS('Casos de prueba'!$B:$B,$A6,'Casos de prueba'!$L:$L,"Bloqueado") | J6: =COUNTIFS('Casos de prueba'!$B:$B,$A6,'Casos de prueba'!$L:$L,"No aplica") | K6: =IF(B6-J6=0,0,(G6+H6+I6)/(B6-J6)) | L6: =IF(G6+H6=0,0,G6/(G6+H6))
A7: Configuración | B7: =COUNTIF('Casos de prueba'!$B:$B,$A7) | C7: =COUNTIFS('Casos de prueba'!$B:$B,$A7,'Casos de prueba'!$F:$F,"Alta") | D7: =COUNTIFS('Casos de prueba'!$B:$B,$A7,'Casos de prueba'!$F:$F,"Media") | E7: =COUNTIFS('Casos de prueba'!$B:$B,$A7,'Casos de prueba'!$F:$F,"Baja") | F7: =COUNTIFS('Casos de prueba'!$B:$B,$A7,'Casos de prueba'!$L:$L,"Pendiente") | G7: =COUNTIFS('Casos de prueba'!$B:$B,$A7,'Casos de prueba'!$L:$L,"Pasó") | H7: =COUNTIFS('Casos de prueba'!$B:$B,$A7,'Casos de prueba'!$L:$L,"Falló") | I7: =COUNTIFS('Casos de prueba'!$B:$B,$A7,'Casos de prueba'!$L:$L,"Bloqueado") | J7: =COUNTIFS('Casos de prueba'!$B:$B,$A7,'Casos de prueba'!$L:$L,"No aplica") | K7: =IF(B7-J7=0,0,(G7+H7+I7)/(B7-J7)) | L7: =IF(G7+H7=0,0,G7/(G7+H7))
A8: Roles y seguridad | B8: =COUNTIF('Casos de prueba'!$B:$B,$A8) | C8: =COUNTIFS('Casos de prueba'!$B:$B,$A8,'Casos de prueba'!$F:$F,"Alta") | D8: =COUNTIFS('Casos de prueba'!$B:$B,$A8,'Casos de prueba'!$F:$F,"Media") | E8: =COUNTIFS('Casos de prueba'!$B:$B,$A8,'Casos de prueba'!$F:$F,"Baja") | F8: =COUNTIFS('Casos de prueba'!$B:$B,$A8,'Casos de prueba'!$L:$L,"Pendiente") | G8: =COUNTIFS('Casos de prueba'!$B:$B,$A8,'Casos de prueba'!$L:$L,"Pasó") | H8: =COUNTIFS('Casos de prueba'!$B:$B,$A8,'Casos de prueba'!$L:$L,"Falló") | I8: =COUNTIFS('Casos de prueba'!$B:$B,$A8,'Casos de prueba'!$L:$L,"Bloqueado") | J8: =COUNTIFS('Casos de prueba'!$B:$B,$A8,'Casos de prueba'!$L:$L,"No aplica") | K8: =IF(B8-J8=0,0,(G8+H8+I8)/(B8-J8)) | L8: =IF(G8+H8=0,0,G8/(G8+H8))
A9: Portal de administración | B9: =COUNTIF('Casos de prueba'!$B:$B,$A9) | C9: =COUNTIFS('Casos de prueba'!$B:$B,$A9,'Casos de prueba'!$F:$F,"Alta") | D9: =COUNTIFS('Casos de prueba'!$B:$B,$A9,'Casos de prueba'!$F:$F,"Media") | E9: =COUNTIFS('Casos de prueba'!$B:$B,$A9,'Casos de prueba'!$F:$F,"Baja") | F9: =COUNTIFS('Casos de prueba'!$B:$B,$A9,'Casos de prueba'!$L:$L,"Pendiente") | G9: =COUNTIFS('Casos de prueba'!$B:$B,$A9,'Casos de prueba'!$L:$L,"Pasó") | H9: =COUNTIFS('Casos de prueba'!$B:$B,$A9,'Casos de prueba'!$L:$L,"Falló") | I9: =COUNTIFS('Casos de prueba'!$B:$B,$A9,'Casos de prueba'!$L:$L,"Bloqueado") | J9: =COUNTIFS('Casos de prueba'!$B:$B,$A9,'Casos de prueba'!$L:$L,"No aplica") | K9: =IF(B9-J9=0,0,(G9+H9+I9)/(B9-J9)) | L9: =IF(G9+H9=0,0,G9/(G9+H9))
A10: Inicio | B10: =COUNTIF('Casos de prueba'!$B:$B,$A10) | C10: =COUNTIFS('Casos de prueba'!$B:$B,$A10,'Casos de prueba'!$F:$F,"Alta") | D10: =COUNTIFS('Casos de prueba'!$B:$B,$A10,'Casos de prueba'!$F:$F,"Media") | E10: =COUNTIFS('Casos de prueba'!$B:$B,$A10,'Casos de prueba'!$F:$F,"Baja") | F10: =COUNTIFS('Casos de prueba'!$B:$B,$A10,'Casos de prueba'!$L:$L,"Pendiente") | G10: =COUNTIFS('Casos de prueba'!$B:$B,$A10,'Casos de prueba'!$L:$L,"Pasó") | H10: =COUNTIFS('Casos de prueba'!$B:$B,$A10,'Casos de prueba'!$L:$L,"Falló") | I10: =COUNTIFS('Casos de prueba'!$B:$B,$A10,'Casos de prueba'!$L:$L,"Bloqueado") | J10: =COUNTIFS('Casos de prueba'!$B:$B,$A10,'Casos de prueba'!$L:$L,"No aplica") | K10: =IF(B10-J10=0,0,(G10+H10+I10)/(B10-J10)) | L10: =IF(G10+H10=0,0,G10/(G10+H10))
A11: Notificaciones | B11: =COUNTIF('Casos de prueba'!$B:$B,$A11) | C11: =COUNTIFS('Casos de prueba'!$B:$B,$A11,'Casos de prueba'!$F:$F,"Alta") | D11: =COUNTIFS('Casos de prueba'!$B:$B,$A11,'Casos de prueba'!$F:$F,"Media") | E11: =COUNTIFS('Casos de prueba'!$B:$B,$A11,'Casos de prueba'!$F:$F,"Baja") | F11: =COUNTIFS('Casos de prueba'!$B:$B,$A11,'Casos de prueba'!$L:$L,"Pendiente") | G11: =COUNTIFS('Casos de prueba'!$B:$B,$A11,'Casos de prueba'!$L:$L,"Pasó") | H11: =COUNTIFS('Casos de prueba'!$B:$B,$A11,'Casos de prueba'!$L:$L,"Falló") | I11: =COUNTIFS('Casos de prueba'!$B:$B,$A11,'Casos de prueba'!$L:$L,"Bloqueado") | J11: =COUNTIFS('Casos de prueba'!$B:$B,$A11,'Casos de prueba'!$L:$L,"No aplica") | K11: =IF(B11-J11=0,0,(G11+H11+I11)/(B11-J11)) | L11: =IF(G11+H11=0,0,G11/(G11+H11))
A12: Pedidos | B12: =COUNTIF('Casos de prueba'!$B:$B,$A12) | C12: =COUNTIFS('Casos de prueba'!$B:$B,$A12,'Casos de prueba'!$F:$F,"Alta") | D12: =COUNTIFS('Casos de prueba'!$B:$B,$A12,'Casos de prueba'!$F:$F,"Media") | E12: =COUNTIFS('Casos de prueba'!$B:$B,$A12,'Casos de prueba'!$F:$F,"Baja") | F12: =COUNTIFS('Casos de prueba'!$B:$B,$A12,'Casos de prueba'!$L:$L,"Pendiente") | G12: =COUNTIFS('Casos de prueba'!$B:$B,$A12,'Casos de prueba'!$L:$L,"Pasó") | H12: =COUNTIFS('Casos de prueba'!$B:$B,$A12,'Casos de prueba'!$L:$L,"Falló") | I12: =COUNTIFS('Casos de prueba'!$B:$B,$A12,'Casos de prueba'!$L:$L,"Bloqueado") | J12: =COUNTIFS('Casos de prueba'!$B:$B,$A12,'Casos de prueba'!$L:$L,"No aplica") | K12: =IF(B12-J12=0,0,(G12+H12+I12)/(B12-J12)) | L12: =IF(G12+H12=0,0,G12/(G12+H12))
A13: Operación y despacho | B13: =COUNTIF('Casos de prueba'!$B:$B,$A13) | C13: =COUNTIFS('Casos de prueba'!$B:$B,$A13,'Casos de prueba'!$F:$F,"Alta") | D13: =COUNTIFS('Casos de prueba'!$B:$B,$A13,'Casos de prueba'!$F:$F,"Media") | E13: =COUNTIFS('Casos de prueba'!$B:$B,$A13,'Casos de prueba'!$F:$F,"Baja") | F13: =COUNTIFS('Casos de prueba'!$B:$B,$A13,'Casos de prueba'!$L:$L,"Pendiente") | G13: =COUNTIFS('Casos de prueba'!$B:$B,$A13,'Casos de prueba'!$L:$L,"Pasó") | H13: =COUNTIFS('Casos de prueba'!$B:$B,$A13,'Casos de prueba'!$L:$L,"Falló") | I13: =COUNTIFS('Casos de prueba'!$B:$B,$A13,'Casos de prueba'!$L:$L,"Bloqueado") | J13: =COUNTIFS('Casos de prueba'!$B:$B,$A13,'Casos de prueba'!$L:$L,"No aplica") | K13: =IF(B13-J13=0,0,(G13+H13+I13)/(B13-J13)) | L13: =IF(G13+H13=0,0,G13/(G13+H13))
A14: Pagos y cartera | B14: =COUNTIF('Casos de prueba'!$B:$B,$A14) | C14: =COUNTIFS('Casos de prueba'!$B:$B,$A14,'Casos de prueba'!$F:$F,"Alta") | D14: =COUNTIFS('Casos de prueba'!$B:$B,$A14,'Casos de prueba'!$F:$F,"Media") | E14: =COUNTIFS('Casos de prueba'!$B:$B,$A14,'Casos de prueba'!$F:$F,"Baja") | F14: =COUNTIFS('Casos de prueba'!$B:$B,$A14,'Casos de prueba'!$L:$L,"Pendiente") | G14: =COUNTIFS('Casos de prueba'!$B:$B,$A14,'Casos de prueba'!$L:$L,"Pasó") | H14: =COUNTIFS('Casos de prueba'!$B:$B,$A14,'Casos de prueba'!$L:$L,"Falló") | I14: =COUNTIFS('Casos de prueba'!$B:$B,$A14,'Casos de prueba'!$L:$L,"Bloqueado") | J14: =COUNTIFS('Casos de prueba'!$B:$B,$A14,'Casos de prueba'!$L:$L,"No aplica") | K14: =IF(B14-J14=0,0,(G14+H14+I14)/(B14-J14)) | L14: =IF(G14+H14=0,0,G14/(G14+H14))
A15: Clientes | B15: =COUNTIF('Casos de prueba'!$B:$B,$A15) | C15: =COUNTIFS('Casos de prueba'!$B:$B,$A15,'Casos de prueba'!$F:$F,"Alta") | D15: =COUNTIFS('Casos de prueba'!$B:$B,$A15,'Casos de prueba'!$F:$F,"Media") | E15: =COUNTIFS('Casos de prueba'!$B:$B,$A15,'Casos de prueba'!$F:$F,"Baja") | F15: =COUNTIFS('Casos de prueba'!$B:$B,$A15,'Casos de prueba'!$L:$L,"Pendiente") | G15: =COUNTIFS('Casos de prueba'!$B:$B,$A15,'Casos de prueba'!$L:$L,"Pasó") | H15: =COUNTIFS('Casos de prueba'!$B:$B,$A15,'Casos de prueba'!$L:$L,"Falló") | I15: =COUNTIFS('Casos de prueba'!$B:$B,$A15,'Casos de prueba'!$L:$L,"Bloqueado") | J15: =COUNTIFS('Casos de prueba'!$B:$B,$A15,'Casos de prueba'!$L:$L,"No aplica") | K15: =IF(B15-J15=0,0,(G15+H15+I15)/(B15-J15)) | L15: =IF(G15+H15=0,0,G15/(G15+H15))
... A24: Transversal | B24: =COUNTIF('Casos de prueba'!$B:$B,$A24) | C24: =COUNTIFS('Casos de prueba'!$B:$B,$A24,'Casos de prueba'!$F:$F,"Alta") | D24: =COUNTIFS('Casos de prueba'!$B:$B,$A24,'Casos de prueba'!$F:$F,"Media") | E24: =COUNTIFS('Casos de prueba'!$B:$B,$A24,'Casos de prueba'!$F:$F,"Baja") | F24: =COUNTIFS('Casos de prueba'!$B:$B,$A24,'Casos de prueba'!$L:$L,"Pendiente") | G24: =COUNTIFS('Casos de prueba'!$B:$B,$A24,'Casos de prueba'!$L:$L,"Pasó") | H24: =COUNTIFS('Casos de prueba'!$B:$B,$A24,'Casos de prueba'!$L:$L,"Falló") | I24: =COUNTIFS('Casos de prueba'!$B:$B,$A24,'Casos de prueba'!$L:$L,"Bloqueado") | J24: =COUNTIFS('Casos de prueba'!$B:$B,$A24,'Casos de prueba'!$L:$L,"No aplica") | K24: =IF(B24-J24=0,0,(G24+H24+I24)/(B24-J24)) | L24: =IF(G24+H24=0,0,G24/(G24+H24))
A25: Total | B25: =SUM(B4:B24) | C25: =SUM(C4:C24) | D25: =SUM(D4:D24) | E25: =SUM(E4:E24) | F25: =SUM(F4:F24) | G25: =SUM(G4:G24) | H25: =SUM(H4:H24) | I25: =SUM(I4:I24) | J25: =SUM(J4:J24) | K25: =IF(B25-J25=0,0,(G25+H25+I25)/(B25-J25)) | L25: =IF(G25+H25=0,0,G25/(G25+H25))
A28: Casos por tipo
A29: Tipo | B29: Casos
A30: Funcional | B30: =COUNTIF('Casos de prueba'!$E:$E,$A30)
A31: Negativo | B31: =COUNTIF('Casos de prueba'!$E:$E,$A31)
A32: Validación | B32: =COUNTIF('Casos de prueba'!$E:$E,$A32)
A33: Permisos | B33: =COUNTIF('Casos de prueba'!$E:$E,$A33)
A34: Seguridad | B34: =COUNTIF('Casos de prueba'!$E:$E,$A34)
A35: Integración | B35: =COUNTIF('Casos de prueba'!$E:$E,$A35)
A36: UI/UX | B36: =COUNTIF('Casos de prueba'!$E:$E,$A36)
A37: Accesibilidad | B37: =COUNTIF('Casos de prueba'!$E:$E,$A37)
A38: Regresión | B38: =COUNTIF('Casos de prueba'!$E:$E,$A38)
A39: Rendimiento | B39: =COUNTIF('Casos de prueba'!$E:$E,$A39)

Sheet Casos de prueba
A1: ID | B1: Módulo | C1: Funcionalidad | D1: Título | E1: Tipo | F1: Prioridad | G1: Rol | H1: Precondiciones | I1: Pasos | J1: Datos de prueba | K1: Resultado esperado | L1: Estado | M1: Resultado obtenido | N1: Ejecutado por | O1: Fecha | P1: Defecto / ticket | Q1: Referencia
A2: LND-001 | B2: Landing y documentación | C2: Landing | D2: La landing en quanela.com sin sesión muestra navegación y llamados a la acción | E2: Funcional | F2: Media | G2: Sin sesión | H2: Navegador sin sesión de Quanela (cookies de .quanela.com borradas). | I2: 1. Abrir https://quanela.com/ 2. Revisar la barra superior 3. Pulsar «Iniciar sesión» 4. Volver y pulsar «Crear cuenta» | K2: Se ve la landing con los enlaces «Producto», «Funcionalidades», «Precios», «FAQ» y «Ayuda». «Iniciar sesión» lleva a /login y «Crear cuenta» lleva a /registro. | L2: Pendiente | Q2: src/modules/landing/components/LandingNav.tsx; ADR 0036
A3: LND-002 | B3: Landing y documentación | C3: Landing con sesión | D3: quanela.com/ sigue mostrando la landing con sesión abierta y ofrece «Ir a mi cuenta» | E3: Regresión | F3: Alta | G3: ADMIN | H3: Sesión abierta como ADMIN de un negocio con subdominio (p. ej. fr3rk6.quanela.com). | I3: 1. Con la sesión abierta, abrir https://quanela.com/ 2. Comprobar que no hay redirección automática al negocio 3. Pulsar «Ir a mi cuenta» en la barra superior | J3: Usuario: laura@negocio.co | K3: quanela.com/ muestra la landing (no redirige al subdominio). La barra muestra «Ir a mi cuenta» en vez de «Iniciar sesión»/«Crear cuenta». Al pulsarlo va a /app y de ahí a la cuenta por defecto en su subdominio ({código}.quanela.com/k/{cuenta}/…). | L3: Pendiente | Q3: ADR 0036; src/app/routes.tsx; src/modules/landing/components/LandingNav.tsx
A4: LND-003 | B4: Landing y documentación | C4: Precios | D4: El botón de cada plan lleva al registro con el plan elegido, o a mi cuenta si ya hay sesión | E4: Funcional | F4: Media | G4: Sin sesión / ADMIN | H4: Planes públicos cargados en la sección «Precios» de la landing. | I4: 1. Sin sesión, ir a la sección «Precios» de la landing 2. Alternar «Mensual» / «Anual» 3. Pulsar el botón de un plan de autoservicio 4. Iniciar sesión, volver a la landing y revisar el mismo botón | K4: Sin sesión, el botón del plan lleva a /registro?plan={clave} y el registro muestra ese plan elegido. Un plan de ventas abre su enlace de contacto. Con sesión, el botón dice «Ir a mi cuenta» y lleva a /app (una organización por persona). | L4: Pendiente | Q4: src/modules/landing/components/PricingSection.tsx; src/shared/plans/plans.ts; ADR 0010
A5: LND-004 | B5: Landing y documentación | C5: Documentación en doc.quanela.com | D5: La ayuda abre en doc.quanela.com sin sesión y «Entrar» lleva al login | E5: Integración | F5: Media | G5: Sin sesión | H5: Sin sesión. Dominio raíz configurado (quanela.com). | I5: 1. En la landing pulsar «Ayuda» (barra superior) 2. Abrir el artículo «Preguntas frecuentes» 3. Pulsar «Entrar» en la cabecera de la documentación | K5: «Ayuda» abre https://doc.quanela.com/ sin pedir sesión ni resolver negocio. Los artículos cargan sin el prefijo /help (p. ej. doc.quanela.com/faq/faq). «Entrar» lleva a https://quanela.com/login. | L5: Pendiente | Q5: ADR 0035; src/modules/help/HelpLayout.tsx; src/modules/help/lib.ts
A6: LND-005 | B6: Landing y documentación | C6: Landing en el celular | D6: El menú móvil de la landing abre y cierra con su botón accesible | E6: Accesibilidad | F6: Baja | G6: Sin sesión | H6: Ventana de 375 px de ancho (celular). | I6: 1. Abrir quanela.com 2. Pulsar el botón de menú (aria-label «Abrir menú») 3. Navegar con Tab por los enlaces 4. Pulsar el mismo botón (ahora «Cerrar menú») | K6: El menú muestra las secciones, «Ayuda», «Iniciar sesión» y «Crear cuenta». La etiqueta accesible cambia entre «Abrir menú» y «Cerrar menú». La página no tiene desplazamiento horizontal. | L6: Pendiente | Q6: src/modules/landing/components/LandingNav.tsx
A7: ACC-001 | B7: Acceso y cuenta | C7: Subdominio del negocio | D7: El subdominio con código válido muestra el login del negocio con su nombre y dirección | E7: Funcional | F7: Alta | G7: Sin sesión | H7: Negocio «Brasa del Barrio» activo con código A7K92P. | I7: 1. Abrir https://a7k92p.quanela.com/ 2. Revisar el subtítulo del login | J7: Código: A7K92P | K7: Se muestra el login «Inicia sesión» con el texto «Entra a Brasa del Barrio en a7k92p.quanela.com.» y el enlace «Ir a Quanela» hacia quanela.com. | L7: Pendiente | Q7: ADR 0021; ADR 0022; src/modules/auth/pages/LoginPage.tsx
A8: ACC-002 | B8: Acceso y cuenta | C8: Subdominio del negocio | D8: Un subdominio con el nombre del negocio o un código inexistente muestra «Esta dirección no existe» | E8: Negativo | F8: Alta | G8: Sin sesión | H8: Existe el negocio «Brasa del Barrio» (slug brasa-del-barrio, código A7K92P). | I8: 1. Abrir https://brasa-del-barrio.quanela.com/ 2. Abrir https://zz99zz.quanela.com/ 3. Pulsar «Ir a Quanela» | J8: Subdominios: brasa-del-barrio, zz99zz | K8: En ambos casos aparece «Esta dirección no existe» con el texto «No hay ningún espacio de Quanela en {dirección}. Revisa que la dirección esté bien escrita.». El nombre no sirve como respaldo. «Ir a Quanela» lleva a quanela.com. | L8: Pendiente | Q8: ADR 0022 (3.2, 3.4); src/shared/tenant/TenantProvider.tsx; supabase/tests/tenants.sql
A9: ACC-003 | B9: Acceso y cuenta | C9: Subdominio del negocio | D9: Un negocio desactivado no deja entrar a nadie | E9: Negativo | F9: Alta | G9: Sin sesión / ADMIN | H9: El Global Admin desactivó el negocio «Brasa del Barrio» (A7K92P). | I9: 1. Abrir https://a7k92p.quanela.com/ 2. Intentar iniciar sesión con un usuario del negocio | J9: Usuario: laura@negocio.co | K9: Aparece «Brasa del Barrio está desactivado» con «Por ahora nadie puede entrar. Si crees que es un error, contacta a quien administra tu negocio.» y el enlace «Ir a Quanela». | L9: Pendiente | Q9: src/shared/tenant/TenantProvider.tsx; ADR 0021 (2.2)
A10: ACC-004 | B10: Acceso y cuenta | C10: Aislamiento por subdominio | D10: Un usuario del negocio A que abre el subdominio del negocio B ve «No tienes acceso» | E10: Seguridad | F10: Alta | G10: ADMIN (negocio A) | H10: Laura es ADMIN solo en el negocio A (código A7K92P). El negocio B tiene código Q3W8RT. | I10: 1. Iniciar sesión en a7k92p.quanela.com 2. Abrir https://q3w8rt.quanela.com/k/{cuenta-de-B}/customers 3. Revisar la pantalla | J10: Usuario: laura@negocio.co | K10: Aparece «No tienes acceso a {Negocio B}» con «Tu usuario no pertenece a este espacio...». Bajo «Tus espacios:» se lista solo el negocio A con su código. Está el botón «Entrar con otro usuario». No se ve ningún dato de B. | L10: Pendiente | Q10: src/shared/tenant/TenantProvider.tsx; supabase/tests/tenants.sql ('Knowing the code of B gives nothing')
A11: ACC-005 | B11: Acceso y cuenta | C11: Sesión compartida | D11: Con un solo inicio de sesión se entra a los dos negocios, y cerrar sesión cierra en todos los subdominios | E11: Integración | F11: Media | G11: CAJA en A / COCINA en B | H11: Andrés es CAJA en el negocio A y COCINA en el negocio B. | I11: 1. Iniciar sesión en el subdominio de A 2. En «Tus cuentas», elegir la cuenta del negocio B 3. Comprobar que no se pide el login otra vez 4. Pulsar «Cerrar sesión» en el menú de usuario 5. Volver al subdominio de A | J11: Usuario: andres@negocio.co | K11: Al elegir la cuenta de B se abre su subdominio con la sesión activa y el rol COCINA. Tras «Cerrar sesión», los dos subdominios muestran su login. | L11: Pendiente | Q11: ADR 0021 (2.3); ADR 0024 (menú de usuario); supabase/tests/tenants.sql ('Membership')
A12: ACC-006 | B12: Acceso y cuenta | C12: Inicio de sesión | D12: Un usuario con correo y contraseña válidos entra a su cuenta y a la pantalla de su rol | E12: Funcional | F12: Alta | G12: CAJA | H12: Usuario activo con rol CAJA en una sola cuenta. | I12: 1. Abrir el subdominio del negocio 2. Escribir el correo en «Correo electrónico» 3. Escribir la contraseña en «Contraseña» 4. Pulsar «Iniciar sesión» | J12: Correo: camila.caja@negocio.co; contraseña de prueba de 8+ caracteres | K12: Entra directo a la cuenta y aterriza en Operación → Tablero (inicio del rol CAJA). Arriba se ve el indicador «Cuenta · CAJA». | L12: Pendiente | Q12: content/help/getting-started/switch-account.md; src/app/navigation.ts (homeSection)
A13: ACC-007 | B13: Acceso y cuenta | C13: Inicio de sesión | D13: Una contraseña incorrecta no inicia sesión y muestra el error en español bajo «Contraseña» | E13: Negativo | F13: Alta | G13: Sin sesión | H13: Usuario activo existente. | I13: 1. Abrir /login 2. Escribir un correo válido 3. Escribir una contraseña equivocada 4. Pulsar «Iniciar sesión» | J13: Correo: laura@negocio.co; contraseña: Clave-Erronea-1 | K13: No se inicia sesión. Aparece un error bajo el campo «Contraseña», en español (p. ej. «Correo o contraseña incorrectos.», como en el portal admin). HALLAZGO: hoy el login de la app muestra el texto de Supabase sin traducir («Invalid login credentials»). | L13: Pendiente | Q13: src/modules/auth/pages/LoginPage.tsx; src/shared/hooks/useAuth.tsx (signIn); admin/src/auth/LoginPage.tsx
A14: ACC-008 | B14: Acceso y cuenta | C14: Inicio de sesión | D14: El parámetro ?next= solo admite rutas internas (no redirige a otro sitio) | E14: Seguridad | F14: Alta | G14: Sin sesión | H14: Usuario activo. | I14: 1. Abrir /login?next=https://sitio-externo.example/robo 2. Iniciar sesión 3. Repetir con /login?next=//sitio-externo.example 4. Repetir con /login?next=/k/{cuenta}/customers | J14: Correo: laura@negocio.co | K14: Con las dos primeras direcciones, después de iniciar sesión se va a /app (la cuenta por defecto), nunca al sitio externo. Con la ruta interna se abre /k/{cuenta}/customers. | L14: Pendiente | Q14: src/modules/auth/pages/LoginPage.tsx (target = next interno o APP_ENTRY)
A15: ACC-009 | B15: Acceso y cuenta | C15: Métodos del dueño (Google/Instagram/teléfono) | D15: Un usuario invitado que entra con Google es devuelto al login con un aviso | E15: Seguridad | F15: Alta | G15: COCINA (invitado) | H15: Sofía fue invitada como COCINA y activó su usuario con correo y contraseña. No es dueña de ningún negocio. Google está activo como método. | I15: 1. En /login, bajo «¿Creaste tu negocio con Google, ...?», pulsar «Continuar con Google» 2. Completar el inicio de sesión con su cuenta de Google del mismo correo 3. Observar a dónde vuelve | J15: Correo: sofia.cocina@negocio.co | K15: Se cierra la sesión y vuelve a /login con el aviso «Esa forma de entrar es para quien creó su negocio en Quanela. Entra con tu correo y tu contraseña.». No entra a la app. | L15: Pendiente | Q15: src/modules/signup/ownerSession.ts (NOT_AN_OWNER_NOTICE); src/modules/signup/pages/SignUpPage.tsx; ADR 0025 (D3)
A16: ACC-010 | B16: Acceso y cuenta | C16: Usuario desactivado | D16: Un usuario desactivado que inicia sesión ve «Usuario desactivado» y solo puede cerrar sesión | E16: Seguridad | F16: Alta | G16: CAJA (desactivado) | H16: Un ADMIN desactivó a Camila desde Usuarios. | I16: 1. Iniciar sesión con el usuario de Camila 2. Intentar abrir /k/{cuenta}/operations | J16: Correo: camila.caja@negocio.co | K16: Aparece «Usuario desactivado» con «{nombre}, tu usuario está desactivado en Quanela. Si crees que es un error, contacta al administrador de tu negocio.» y el botón «Cerrar sesión». No se puede abrir ninguna ruta de la cuenta. | L16: Pendiente | Q16: src/modules/auth/pages/AccountDisabledPage.tsx; src/app/ProtectedRoute.tsx
A17: ACC-011 | B17: Acceso y cuenta | C17: Acceso sin sesión | D17: Una ruta protegida abierta sin sesión lleva al login | E17: Seguridad | F17: Alta | G17: Sin sesión | H17: Sin sesión en el navegador. | I17: 1. Abrir directamente https://{código}.quanela.com/k/{cuenta}/users 2. Abrir /k/{cuenta}/settings/general 3. Abrir /cuentas | K17: En todos los casos se redirige a /login y no se carga ningún dato de la cuenta. Nota: el login no recuerda la ruta pedida (no agrega ?next=), así que después de entrar se va a /app. | L17: Pendiente | Q17: src/app/ProtectedRoute.tsx; src/app/routes.tsx
A18: ACC-012 | B18: Acceso y cuenta | C18: Registro del dueño | D18: Crear un negocio con correo de principio a fin | E18: Funcional | F18: Alta | G18: Sin sesión (dueño nuevo) | H18: Registro público activo. El correo no existe en Quanela. | I18: 1. Abrir quanela.com/registro 2. Paso 1 de 3: pulsar «Continuar con email», escribir «Tu nombre», «Correo» y «Contraseña», y pulsar «Continuar» 3. Paso 2 de 3: pulsar «Elegir» en un plan 4. Paso 3 de 3: completar «Nombre del negocio», «Sector», «Categoría», «Ciudad» y «País», y dejar vacío «Nombre de la cuenta» 5. Pulsar «Crear mi negocio» 6. Abrir el enlace del correo de confirmación 7. Pulsar «Entrar a mi espacio» | J18: Laura Gómez; laura@negocio.co; Hamburguesas La Esquina; Comida rápida / Hamburguesas; Bogotá; Colombia | K18: Tras «Crear mi negocio» aparece «Revisa tu correo». Al confirmar se ve «Tu cuenta ha sido creada» con «Código: XXXXXX» (6 caracteres, mayúsculas) y «Tu espacio Quanela: xxxxxx.quanela.com», con botón para copiar la dirección. «Entrar a mi espacio» abre la cuenta «Hamburguesas La Esquina» (toma el nombre del negocio) con la tarjeta de bienvenida y sus atajos. Laura queda como SUPER_ADMIN y ADMIN de la primera cuenta. | L18: Pendiente | Q18: content/help/getting-started/create-business.md; src/modules/signup/pages/SignUpPage.tsx; src/modules/signup/pages/SignUpConfirmedPage.tsx; supabase/tests/signup.sql; supabase/tests/plans.sql
A19: ACC-013 | B19: Acceso y cuenta | C19: Registro del dueño | D19: Validaciones del paso «Crea tu usuario» | E19: Validación | F19: Alta | G19: Sin sesión | H19: En /registro, «Continuar con email». | I19: 1. Escribir «L» en «Tu nombre» 2. Escribir «laura.negocio.co» en «Correo» 3. Cambiarlo a «laura@negocio» 4. Escribir «1234567» en «Contraseña» 5. Corregir todos los campos | J19: Nombre: L; correos: laura.negocio.co / laura@negocio; contraseña: 1234567 | K19: Errores en orden: «Mínimo 2 caracteres» (nombre), «Falta la @ del correo.», «Falta el dominio del correo (por ejemplo, @gmail.com).» y «Mínimo 8 caracteres» (contraseña). «Continuar» sigue deshabilitado hasta corregir todo. | L19: Pendiente | Q19: src/modules/signup/pages/SignUpPage.tsx; src/shared/utils/email.ts (emailError)
A20: ACC-014 | B20: Acceso y cuenta | C20: Registro del dueño | D20: Campos obligatorios y teléfono con país en «Tu negocio y tu primera cuenta» | E20: Validación | F20: Media | G20: Sin sesión | H20: Paso 3 de 3 del registro, con plan elegido. | I20: 1. Dejar vacíos «Sector» y «Categoría» 2. Escribir un teléfono inválido en «Teléfono (opcional)» con Colombia 3. Corregir el teléfono a un celular válido 4. Completar «Sector» y «Categoría» | J20: Teléfono inválido: 123 456; válido: 300 123 4567 (🇨🇴 +57) | K20: «Crear mi negocio» está deshabilitado mientras falten «Nombre del negocio», «Sector» o «Categoría», o el teléfono sea inválido. El teléfono inválido muestra «Revisa el número: en Colombia, un celular empieza por 3 y tiene 10 dígitos (un fijo, por 60).». El válido se guarda normalizado como +573001234567. | L20: Pendiente | Q20: src/modules/signup/pages/SignUpPage.tsx; src/shared/utils/phone.ts; ADR 0039
A21: ACC-015 | B21: Acceso y cuenta | C21: Registro del dueño | D21: Registrarse con un correo que ya tiene usuario muestra cómo entrar | E21: Negativo | F21: Media | G21: Sin sesión | H21: Ya existe un usuario con laura@negocio.co. | I21: 1. Completar los 3 pasos del registro con ese correo 2. Pulsar «Crear mi negocio» | J21: Correo: laura@negocio.co | K21: No se crea nada y aparece «Ese correo ya tiene usuario en Quanela. Inicia sesión.». El enlace «¿Ya tienes usuario? Inicia sesión» lleva a /login. | L21: Pendiente | Q21: src/modules/signup/pages/SignUpPage.tsx (submit)
A22: ACC-016 | B22: Acceso y cuenta | C22: Registro por teléfono | D22: Registro con teléfono y código SMS, con reenvío y código incorrecto | E22: Funcional | F22: Media | G22: Sin sesión | H22: Método teléfono activo; el número recibe SMS de prueba. | I22: 1. En /registro pulsar «Continuar con teléfono» 2. Elegir 🇨🇴 Colombia, escribir el celular y pulsar «Enviarme el código» 3. Escribir un código equivocado de 6 dígitos y pulsar «Verificar» 4. Esperar a que «Reenviar en N s» cambie a «Reenviar el código» 5. Escribir el código correcto y pulsar «Verificar» | J22: Celular: 300 123 4567; código erróneo: 000000 | K22: «Verificar» se habilita con 6 dígitos (solo números). El código erróneo muestra «El código no es correcto o ya venció. Pide uno nuevo.». El reenvío se habilita a los 60 s. Con el código correcto el registro sigue al paso del plan o del negocio, con «Entraste como +573001234567». | L22: Pendiente | Q22: src/modules/signup/components/OwnerMethods.tsx; src/modules/signup/ownerAuth.ts; ADR 0025
A23: ACC-017 | B23: Acceso y cuenta | C23: Registro del dueño | D23: Un dueño que ya tiene negocio no puede crear un segundo | E23: Negativo | F23: Alta | G23: SUPER_ADMIN (dueño) | H23: Laura ya creó «Hamburguesas La Esquina» y tiene la sesión abierta. | I23: 1. Abrir quanela.com/registro con la sesión abierta | J23: Correo: laura@negocio.co | K23: Se redirige a /app (su cuenta). No aparece el formulario y no se crea otra organización: una persona es dueña de una sola (si se repite la creación, se devuelve la misma cuenta). | L23: Pendiente | Q23: src/modules/signup/pages/SignUpPage.tsx (D4); supabase/tests/signup.sql ('Quien ya es dueño no crea una segunda organización')
A24: ACC-018 | B24: Acceso y cuenta | C24: Registro del dueño | D24: Registrarse con el correo de una invitación pendiente se bloquea | E24: Negativo | F24: Media | G24: Sin sesión | H24: Un ADMIN creó a «Mario Ruiz» (mario@negocio.co) y su usuario sigue «Pendiente». | I24: 1. En /registro, registrarse con mario@negocio.co 2. Confirmar el correo y volver a la app | J24: Correo: mario@negocio.co | K24: No se crea el negocio ni un segundo perfil. Aparece «No pudimos terminar» con el mensaje de invitación pendiente («tienes una invitación pendiente; actívala con el enlace que te enviaron»). Revisar que no se vea el prefijo técnico «PENDING_INVITATION:». | L24: Pendiente | Q24: supabase/tests/owner_signup.sql ('Invitations'); supabase/migrations/20261005100000_dk_owner_signup_methods.sql; src/modules/signup/pages/SignUpConfirmedPage.tsx
A25: ACC-019 | B25: Acceso y cuenta | C25: Enlace para crear contraseña | D25: Crear la contraseña desde un enlace de /set-password | E25: Validación | F25: Media | G25: Sin sesión | H25: Enlace de contraseña generado desde el portal (vigente 1 hora, un solo uso). | I25: 1. Abrir el enlace 2. Escribir contraseñas distintas en «Nueva contraseña» y «Repítela» y pulsar «Guardar contraseña» 3. Escribir la misma contraseña anterior en los dos campos 4. Escribir una contraseña nueva válida en los dos 5. Volver a abrir el mismo enlace | K25: Distintas: «Las contraseñas no coinciden.». Igual a la anterior: «Usa una contraseña distinta a la anterior.». Válida: «Contraseña guardada» con «Entrar a Quanela». Reabrir el enlace: «El enlace ya se usó o venció» con «Los enlaces para crear contraseña son de un solo uso y vencen en poco tiempo...». | L25: Pendiente | Q25: src/modules/auth/pages/SetPasswordPage.tsx; supabase/tests/password_link.sql
A26: ACC-020 | B26: Acceso y cuenta | C26: Cambiar de rol | D26: Una persona con dos roles cambia de rol desde el indicador y la interfaz se adapta | E26: Funcional | F26: Alta | G26: CAJA + COCINA | H26: Andrés tiene CAJA (predeterminado) y COCINA en la misma cuenta. | I26: 1. Pulsar el indicador «Cuenta · CAJA» arriba 2. En «Trabajar como», elegir COCINA 3. Revisar el menú lateral y la pantalla actual 4. Con el menú de usuario → «Cambiar de rol», volver a CAJA | J26: Usuario: andres@negocio.co | K26: Aparece el aviso «Ahora trabajas como COCINA.». El menú muestra solo Operación y Catálogo. Si la pantalla actual no es del rol nuevo (p. ej. Clientes), lleva a su inicio (Operación → Cocina). Al volver a CAJA reaparecen Inicio, Clientes e Insights. | L26: Pendiente | Q26: src/app/AccountSwitcher.tsx (RoleList); src/app/AppLayout.tsx; content/help/intro/roles.md
A27: ACC-021 | B27: Acceso y cuenta | C27: Menú de usuario | D27: El menú de usuario se usa con el teclado | E27: Accesibilidad | F27: Media | G27: ADMIN | H27: Sesión iniciada en escritorio. | I27: 1. Llevar el foco con Tab al avatar (aria-label «Menú de usuario: {nombre}») y pulsar Enter 2. Recorrer con ↑/↓ 3. En «Apariencia» pulsar → 4. Pulsar ← para cerrar el submenú 5. Pulsar Esc | K27: El menú se abre con Enter, ↑/↓ recorren las opciones, → abre el submenú lateral, ← lo cierra y Esc cierra el menú. El foco vuelve al avatar. | L27: Pendiente | Q27: ADR 0023 (sección 2); src/shared/ui/MenuPanel.tsx; src/app/help/HelpDialogs.tsx (atajos)
A28: ACC-022 | B28: Acceso y cuenta | C28: Mi perfil | D28: Cambiar la contraseña desde «Mi perfil» | E28: Validación | F28: Alta | G28: CAJA | H28: Sesión iniciada con correo y contraseña. | I28: 1. Menú de usuario → «Mi perfil» → tarjeta «Contraseña» 2. Escribir mal la «Contraseña actual», una nueva válida, y pulsar «Cambiar contraseña» 3. Escribir 7 caracteres en «Nueva contraseña» 4. Escribir en «Nueva contraseña» la misma contraseña actual 5. Escribir en «Repite la nueva» un valor distinto 6. Completar todo bien y pulsar «Cambiar contraseña» | K28: Actual incorrecta: aviso «La contraseña actual no es correcta». Se ven «Mínimo 8 caracteres», «Debe ser distinta de la actual» y «No coincide». Con todo correcto: «Contraseña actualizada.» y los campos se vacían. | L28: Pendiente | Q28: src/modules/profile/pages/ProfilePage.tsx; src/modules/profile/api/profile.ts
A29: ACC-023 | B29: Acceso y cuenta | C29: Usuario sin negocio | D29: Un usuario que no pertenece a ningún negocio ve un mensaje con la marca Quanela | E29: UI/UX | F29: Baja | G29: Usuario autenticado sin negocio | H29: Usuario de prueba con sesión válida pero sin perfil en ninguna organización. | I29: 1. Iniciar sesión con ese usuario 2. Leer el mensaje de la pantalla | J29: sinnegocio@prueba.co | K29: El mensaje dice que el usuario aún no pertenece a ningún negocio en Quanela (no «Dark Kitchen») y ofrece cerrar sesión. | L29: Pendiente | Q29: src/modules/auth/pages/NoProfilePage.tsx
A30: ACC-024 | B30: Acceso y cuenta | C30: Regreso tras iniciar sesión | D30: Tras iniciar sesión se vuelve a la página protegida que se había pedido | E30: UI/UX | F30: Media | G30: CAJA | H30: Sin sesión. Usuario CAJA activo. | I30: 1. Abrir directamente la URL de Clientes del negocio 2. Iniciar sesión en el login al que redirige 3. Ver a qué pantalla llega | K30: Después de iniciar sesión se abre Clientes, la página que se pidió (la URL del login lleva ?next=). Hoy se llega a la pantalla de inicio del rol: anotar como defecto si pasa. | L30: Pendiente | Q30: src/modules/auth; src/app/routes.tsx
A31: EQP-001 | B31: Equipo | C31: Crear usuario (invitación) | D31: Un ADMIN crea un usuario y obtiene el enlace de activación | E31: Funcional | F31: Alta | G31: ADMIN | H31: ADMIN en una cuenta con plan disponible para más usuarios. | I31: 1. Abrir «Usuarios» y pulsar «Crear usuario» 2. Escribir «Nombre» y «Correo» 3. En «Roles en esta cuenta» marcar COCINA 4. Pulsar «Crear usuario» 5. En «Usuario creado», pulsar «Copiar» 6. Cerrar y buscar a la persona en la lista | J31: Sofía Martínez; sofia.cocina@negocio.co; rol COCINA | K31: Aparece «Usuario creado» con el enlace y el texto «Envíale este enlace a Sofía Martínez (sofia.cocina@negocio.co) por WhatsApp o correo... Vence en 7 días.» y «Por seguridad no se vuelve a mostrar...». «Copiar» muestra «Enlace copiado.». En la lista, Sofía aparece con estado «Pendiente». | L31: Pendiente | Q31: content/help/getting-started/invite-team.md; src/modules/organization/components/UserDrawer.tsx; src/modules/organization/components/ActivationLinkModal.tsx; supabase/tests/org_users.sql
A32: EQP-002 | B32: Equipo | C32: Crear usuario (invitación) | D32: Validaciones del formulario «Crear usuario» | E32: Validación | F32: Alta | G32: ADMIN | H32: Panel «Crear usuario» abierto en un negocio con 2 cuentas. | I32: 1. Escribir «S» en «Nombre» 2. Escribir «sofia@negocio» en «Correo» 3. Desmarcar todas las cuentas 4. Marcar una cuenta y quitarle todos los roles | J32: Nombre: S; correo: sofia@negocio | K32: Se ven «Mínimo 2 caracteres», «Falta el dominio del correo (por ejemplo, @gmail.com).», «Asígnale al menos una cuenta.» y «Elige al menos un rol.». El botón «Crear usuario» queda deshabilitado mientras haya errores. | L32: Pendiente | Q32: src/modules/organization/components/UserDrawer.tsx
A33: EQP-003 | B33: Equipo | C33: Activación de usuario | D33: La persona invitada activa su usuario con el enlace y entra a su cuenta | E33: Funcional | F33: Alta | G33: Sin sesión (invitado) | H33: Existe el enlace vigente de Sofía (COCINA). Sofía no tiene usuario en Quanela. | I33: 1. Abrir el enlace /activar/{token} 2. Verificar el encabezado 3. Escribir una contraseña de 7 caracteres en «Crea tu contraseña» 4. Completarla a 8 o más caracteres 5. Pulsar «Activar mi usuario» | J33: Contraseña de prueba de 8+ caracteres | K33: Se ve «Activa tu usuario», el nombre del negocio y «Hola, Sofía Martínez · sofia.cocina@negocio.co». El «Correo» es de solo lectura. «Activar mi usuario» se habilita con 8 caracteres o más. Al activar entra a su cuenta como COCINA (Operación → Cocina) y en Usuarios su estado pasa a «Activo». | L33: Pendiente | Q33: src/modules/invitations/pages/ActivationPage.tsx; supabase/tests/org_users.sql ('Activación')
A34: EQP-004 | B34: Equipo | C34: Activación de usuario | D34: Enlaces de activación usados, vencidos, reemplazados o incompletos | E34: Negativo | F34: Alta | G34: Sin sesión | H34: Tener 4 enlaces de prueba: uno ya usado, uno vencido (más de 7 días), uno reemplazado por «Generar enlace nuevo» y uno con el token cortado. | I34: 1. Abrir cada enlace en una ventana privada | K34: Usado: «Este enlace ya se usó. Si es tuyo, solo inicia sesión.». Vencido: «Este enlace venció. Pide a tu administrador uno nuevo.». Reemplazado: «Este enlace fue reemplazado por uno más nuevo. Usa el último que te enviaron.». Cortado: «Enlace no válido» y «Revisa que el enlace esté completo o pide uno nuevo a tu administrador.». Todos ofrecen «Ir a iniciar sesión» y ninguno activa al usuario. | L34: Pendiente | Q34: src/modules/invitations/pages/ActivationPage.tsx (STATUS_MESSAGE); supabase/tests/org_users.sql ('Reusar el enlace')
A35: EQP-005 | B35: Equipo | C35: Activación de usuario | D35: «Generar enlace nuevo» invalida el enlace anterior | E35: Seguridad | F35: Alta | G35: ADMIN | H35: Sofía está «Pendiente» y tiene un enlace vigente (enlace 1). | I35: 1. Abrir la ficha de Sofía en Usuarios 2. Verificar el texto «Pendiente de activación · el enlace vence el {fecha}» 3. Pulsar «Generar enlace nuevo» y copiar el enlace 2 4. Abrir el enlace 1 en una ventana privada 5. Abrir el enlace 2 | K35: El enlace 1 muestra «Este enlace fue reemplazado por uno más nuevo. Usa el último que te enviaron.». El enlace 2 permite activar. | L35: Pendiente | Q35: content/help/getting-started/invite-team.md; src/modules/organization/components/UserDrawer.tsx; supabase/tests/password_link.sql ('Old activation link revoked')
A36: EQP-006 | B36: Equipo | C36: Activación de usuario | D36: Abrir un enlace de activación con la sesión de otro correo no lo activa | E36: Seguridad | F36: Alta | G36: CAJA (otra persona) | H36: Sesión abierta como camila.caja@negocio.co. Enlace vigente de Sofía. | I36: 1. Con esa sesión, abrir el enlace de Sofía | K36: Aparece «Entraste como camila.caja@negocio.co, pero este enlace es para sofia.cocina@negocio.co. Cierra sesión y entra con ese correo.» con el botón «Cerrar sesión». La invitación no se activa. | L36: Pendiente | Q36: src/modules/invitations/pages/ActivationPage.tsx; supabase/tests/org_users.sql ('Activar con otro correo')
A37: EQP-007 | B37: Equipo | C37: Activación de usuario | D37: Una persona que ya tiene usuario en otro negocio se une con su mismo perfil | E37: Integración | F37: Media | G37: CAJA (en otro negocio) | H37: Andrés es CAJA en el negocio A. El ADMIN del negocio B lo invita como COCINA. | I37: 1. Abrir el enlace de B sin sesión 2. Pulsar «Iniciar sesión» 3. Iniciar sesión con su correo y contraseña 4. Pulsar «Activar y entrar a {Negocio B}» 5. Abrir «Tus cuentas» | J37: Correo: andres@negocio.co | K37: Sin sesión se ve «Ya tienes usuario en Quanela. Inicia sesión con tu correo para unirte a {Negocio B}.» y la opción «Aún no tengo contraseña: envíame un enlace». Tras iniciar sesión vuelve al enlace (login?next=/activar/...). Al activar entra a la cuenta de B como COCINA. En «Tus cuentas» ve las dos cuentas con un solo usuario y perfil. | L37: Pendiente | Q37: src/modules/invitations/pages/ActivationPage.tsx; supabase/tests/org_users.sql ('Identidad')
A38: EQP-008 | B38: Equipo | C38: Usuarios | D38: Cambiar los roles de una persona y con cuál «Entra como» | E38: Funcional | F38: Alta | G38: ADMIN | H38: Negocio con 2 cuentas. Camila tiene CAJA en «Brasa Centro». | I38: 1. Abrir «Usuarios» y pulsar sobre Camila 2. Agregarle COCINA en «Brasa Centro» 3. En «Entra como», elegir CAJA 4. Pulsar «Aplicar a todas las cuentas» 5. Pulsar «Guardar cambios» | J38: Usuario: camila.caja@negocio.co | K38: Aparece «Cambios guardados.». Camila tiene CAJA y COCINA en las dos cuentas y entra como CAJA. En su próxima sesión, el indicador permite cambiar entre los dos roles. | L38: Pendiente | Q38: content/help/team/users-and-roles.md; src/modules/organization/components/UserDrawer.tsx
A39: EQP-009 | B39: Equipo | C39: Usuarios | D39: Desactivar y volver a activar a una persona | E39: Funcional | F39: Alta | G39: SUPER_ADMIN (dueño) | H39: Camila está activa en 2 cuentas. | I39: 1. Abrir la ficha de Camila y pulsar «Desactivar» 2. Leer el diálogo «Desactivar usuario» y pulsar «Sí, desactivar» 3. En otra ventana, intentar entrar como Camila 4. Volver a la ficha y pulsar «Activar» → «Sí, activar» | K39: El diálogo dice «Camila ... pierde el acceso de inmediato. Aplica a todas tus cuentas.». Aparece «{nombre} ya no tiene acceso.» y su estado pasa a «Desactivado». Camila no puede operar en ninguna cuenta. Al activarla: «{nombre} vuelve a tener acceso.» con los mismos roles. | L39: Pendiente | Q39: src/modules/organization/components/UserDrawer.tsx; supabase/tests/org_users.sql ('Desactivar')
A40: EQP-010 | B40: Equipo | C40: Usuarios | D40: Nadie cambia sus propios roles ni su estado, y el SUPER_ADMIN no se puede desactivar | E40: Permisos | F40: Alta | G40: ADMIN / SUPER_ADMIN | H40: Laura es SUPER_ADMIN (creó el negocio). Pablo es ADMIN invitado. | I40: 1. Como Pablo, abrir su propia ficha en «Usuarios» 2. Como Pablo, abrir la ficha de Laura 3. Por API, como Pablo, llamar a la función para desactivar a Laura | K40: En su propia ficha, Pablo ve la insignia «Tú», con los roles deshabilitados y sin «Desactivar» ni «Quitar de esta cuenta». En la ficha de Laura se ve la insignia «SUPER_ADMIN», la nota de que es intransferible, y no aparecen «Desactivar» ni «Quitar». La API rechaza el cambio. | L40: Pendiente | Q40: src/modules/organization/components/UserDrawer.tsx (lockedStatus/lockedRoles); supabase/tests/org_users.sql ('SUPER_ADMIN'); supabase/tests/account_scope.sql ('Cannot remove yourself')
...

Sheet Posibles defectos
A1: # | B1: Severidad | C1: Módulo | D1: Descripción | E1: Dónde (código) | F1: Casos relacionados | G1: Estado | H1: Notas
A2: 1 | B2: Alta | C2: Cocina | D2: Si un plato vuelve de «Listo» a un estado anterior y luego otra vez a «Listo», el inventario no se descuenta de nuevo; si después se cancela, el stock se devuelve dos veces. | E2: supabase/migrations/20260915230656_dk_kitchen_revert_cancel_sla_settings.sql, 20260912233856_dk_kitchen_workflow.sql | F2: COC-006, COC-007, PED-014 | G2: Por confirmar
A3: 2 | B3: Alta | C3: Clientes | D3: Editar un cliente desde el menú ⋯ de la lista borra su correo (el formulario abre sin él y guarda vacío). Desde la ficha del cliente funciona bien. | E3: src/modules/customers/components/CustomerActions.tsx | F3: CLI-021 | G3: Por confirmar
A4: 3 | B4: Alta | C4: Copilot | D4: La conversación guardada de Copilot depende solo de la cuenta: al cambiar de rol o de usuario en la misma pestaña (30 min) puede verse y enviarse lo que respondió al rol anterior. Cerrar sesión no la borra. | E4: src/modules/copilot/lib/conversation.ts | F4: COP-011, TRV-013 | G4: Por confirmar
A5: 4 | B5: Alta | C5: Insights | D5: El CSV exportado no neutraliza celdas que empiezan por =, +, - o @: un plato llamado «=HYPERLINK(...)» se ejecuta como fórmula en Excel. | E5: src/modules/insights/lib/csv.ts | F5: INS-014 | G5: Por confirmar
A6: 5 | B6: Alta | C6: Catálogo y menú | D6: COCINA ve los controles del planificador (arrastrar, +, ×, reglas) pero la base solo le deja cambiar el día de hoy: agregar falla con error de seguridad y editar otro día puede mostrar éxito sin guardar. | E6: src/modules/menuPlanner | F6: CAT-020 | G6: Por confirmar
A7: 6 | B7: Alta | C7: Catálogo y menú | D7: Las reglas del día (precio promocional, agotado, horario, límite de unidades) no se aplican al crear pedidos a mano; el límite y el horario no se aplican en ningún lado. | E7: src/modules/orders, src/modules/menuPlanner | F7: CAT-016 | G7: Por confirmar
A8: 7 | B8: Alta | C8: Transversal | D8: Pegar un monto con punto decimal en un campo de dinero («85000.50») se convierte en 8.500.050. | E8: src/shared/components (CurrencyInput), src/shared/utils/numberInput.ts | F8: TRV-014 | G8: Por confirmar
A9: 8 | B9: Media | C9: Acceso y cuenta | D9: El inicio de sesión de la app muestra el error de Supabase en inglés («Invalid login credentials»); el portal de administración sí lo traduce. | E9: src/modules/auth/pages/LoginPage.tsx, src/shared/hooks/useAuth.tsx | F9: ACC-007 | G9: Por confirmar
A10: 9 | B10: Media | C10: Pedidos / Abastecimiento | D10: Algunos errores muestran el ID interno en lugar del nombre: «El plato <id> no tiene una receta activa», «Stock insuficiente para el insumo <id>», «No hay conversion definida…». | E10: supabase/migrations (dk_confirm_order, reservas) | F10: PED-008, PED-009, ABA-009 | G10: Por confirmar
A11: 10 | B11: Media | C11: Varios | D11: Errores técnicos llegan crudos a la pantalla: «PENDING_INVITATION: …» al registrarse, «Hasta» antes de «Desde», máximo menor que mínimo, código de insumo duplicado, línea de compra con cantidad 0. | E11: src/shared/utils (getErrorMessage) | F11: ACC-018, CAT-013, ABA-003 | G11: Por confirmar
A12: 11 | B12: Media | C12: Pagos y cartera | D12: «Vencido» nunca se activa: dk_orders.due_date no se llena, así que el filtro «Vencidos», «Saldo vencido» y el aviso de cliente moroso siempre dan cero. | E12: docs/adr/0031-centro-de-operaciones.md | F12: PAG-016 | G12: Por confirmar
A13: 12 | B13: Media | C13: Clientes | D13: Se puede registrar una queja ya «Resuelta» sin «Respuesta o solución»; al cerrarla desde el seguimiento sí se exige. | E13: src/modules/customers/components/profile | F13: CLI-024, CLI-017 | G13: Por confirmar
... A30: 29 | B30: Baja | C30: Centro de ayuda | D30: Desajustes de la ayuda con el código: el artículo de Insights no incluye a CAJA en su audiencia, y «Facturación» solo la ve el dueño (SUPER_ADMIN), no un ADMIN invitado. | E30: content/help/reports/insights.md, content/help/settings/settings.md | F30: CFG-003, INS-006 | G30: Por confirmar
